<?xml version="1.0"?>
    <robot name="robot">


    <!-- body -->
    <link name="body">
        <inertial>
            <origin xyz="0 0 0" rpy="0 0 0"/>
            <mass value="100"/>
            <inertia ixx="15" ixy="0" ixz="0" iyy="15" iyz="0" izz="15"/>
        </inertial>
        <visual>
            <origin xyz="0 0 0" rpy="0 0 0"/>
            <geometry>
                <box size="1 1 1"/>
            </geometry>
        </visual>
        <collision>
            <origin xyz="0 0 0" rpy="0 0 0"/>
            <geometry>
                <box size="1 1 1"/>
            </geometry>
        </collision>
    </link>


    <!-- body_sensor_0_start -->
    <link name="body_sensor_0_start">
        <inertial>
            <origin xyz="0 0 0" rpy="0 0 0"/>
            <mass value="0"/>
            <inertia ixx="0" ixy="0" ixz="0" iyy="0" iyz="0" izz="0"/>
        </inertial>
        <visual>
            <origin xyz="0 0 0" rpy="0 0 0"/>
            <geometry>
                <box size="0.02 1 1"/>
            </geometry>
        </visual>
        <collision>
            <origin xyz="0 0 0" rpy="0 0 0"/>
            <geometry>
                <box size="0.02 1 1"/>
            </geometry>
        </collision>
    </link>
    <!-- Joint: body, body_sensor_0_start -->
    <joint name="body_body_sensor_0_start_joint" type="fixed">
        <parent link="body"/>
        <child link="body_sensor_0_start"/>
        <origin xyz="0.5 0 0"
                rpy="0 0 0"/>
        <axis xyz="0 0 1"/>
        
    </joint>


    <!-- body_sensor_0_stop -->
    <link name="body_sensor_0_stop">
        <inertial>
            <origin xyz="0 0 0" rpy="0 0 0"/>
            <mass value="0"/>
            <inertia ixx="0" ixy="0" ixz="0" iyy="0" iyz="0" izz="0"/>
        </inertial>
        <visual>
            <origin xyz="0 0 0" rpy="0 0 0"/>
            <geometry>
                <box size="0.02 1 1"/>
            </geometry>
        </visual>
        <collision>
            <origin xyz="0 0 0" rpy="0 0 0"/>
            <geometry>
                <box size="0.02 1 1"/>
            </geometry>
        </collision>
    </link>
    <!-- Joint: body, body_sensor_0_stop -->
    <joint name="body_body_sensor_0_stop_joint" type="fixed">
        <parent link="body"/>
        <child link="body_sensor_0_stop"/>
        <origin xyz="-0.5 0 0"
                rpy="0 0 0"/>
        <axis xyz="0 0 1"/>
        
    </joint>


    <!-- body_sensor_0_top -->
    <link name="body_sensor_0_top">
        <inertial>
            <origin xyz="0 0 0" rpy="0 0 0"/>
            <mass value="0"/>
            <inertia ixx="0" ixy="0" ixz="0" iyy="0" iyz="0" izz="0"/>
        </inertial>
        <visual>
            <origin xyz="0 0 0" rpy="0 0 0"/>
            <geometry>
                <box size="1.0 1 0.02"/>
            </geometry>
        </visual>
        <collision>
            <origin xyz="0 0 0" rpy="0 0 0"/>
            <geometry>
                <box size="1.0 1 0.02"/>
            </geometry>
        </collision>
    </link>
    <!-- Joint: body, body_sensor_0_top -->
    <joint name="body_body_sensor_0_top_joint" type="fixed">
        <parent link="body"/>
        <child link="body_sensor_0_top"/>
        <origin xyz="0 0 0.5"
                rpy="0 0 0"/>
        <axis xyz="0 0 1"/>
        
    </joint>


    <!-- body_sensor_0_bottom -->
    <link name="body_sensor_0_bottom">
        <inertial>
            <origin xyz="0 0 0" rpy="0 0 0"/>
            <mass value="0"/>
            <inertia ixx="0" ixy="0" ixz="0" iyy="0" iyz="0" izz="0"/>
        </inertial>
        <visual>
            <origin xyz="0 0 0" rpy="0 0 0"/>
            <geometry>
                <box size="1.0 1 0.02"/>
            </geometry>
        </visual>
        <collision>
            <origin xyz="0 0 0" rpy="0 0 0"/>
            <geometry>
                <box size="1.0 1 0.02"/>
            </geometry>
        </collision>
    </link>
    <!-- Joint: body, body_sensor_0_bottom -->
    <joint name="body_body_sensor_0_bottom_joint" type="fixed">
        <parent link="body"/>
        <child link="body_sensor_0_bottom"/>
        <origin xyz="0 0 -0.5"
                rpy="0 0 0"/>
        <axis xyz="0 0 1"/>
        
    </joint>


    <!-- body_sensor_0_left -->
    <link name="body_sensor_0_left">
        <inertial>
            <origin xyz="0 0 0" rpy="0 0 0"/>
            <mass value="0"/>
            <inertia ixx="0" ixy="0" ixz="0" iyy="0" iyz="0" izz="0"/>
        </inertial>
        <visual>
            <origin xyz="0 0 0" rpy="0 0 0"/>
            <geometry>
                <box size="1.0 0.02 1"/>
            </geometry>
        </visual>
        <collision>
            <origin xyz="0 0 0" rpy="0 0 0"/>
            <geometry>
                <box size="1.0 0.02 1"/>
            </geometry>
        </collision>
    </link>
    <!-- Joint: body, body_sensor_0_left -->
    <joint name="body_body_sensor_0_left_joint" type="fixed">
        <parent link="body"/>
        <child link="body_sensor_0_left"/>
        <origin xyz="0 0.5 0"
                rpy="0 0 0"/>
        <axis xyz="0 0 1"/>
        
    </joint>


    <!-- body_sensor_0_right -->
    <link name="body_sensor_0_right">
        <inertial>
            <origin xyz="0 0 0" rpy="0 0 0"/>
            <mass value="0"/>
            <inertia ixx="0" ixy="0" ixz="0" iyy="0" iyz="0" izz="0"/>
        </inertial>
        <visual>
            <origin xyz="0 0 0" rpy="0 0 0"/>
            <geometry>
                <box size="1.0 0.02 1"/>
            </geometry>
        </visual>
        <collision>
            <origin xyz="0 0 0" rpy="0 0 0"/>
            <geometry>
                <box size="1.0 0.02 1"/>
            </geometry>
        </collision>
    </link>
    <!-- Joint: body, body_sensor_0_right -->
    <joint name="body_body_sensor_0_right_joint" type="fixed">
        <parent link="body"/>
        <child link="body_sensor_0_right"/>
        <origin xyz="0 -0.5 0"
                rpy="0 0 0"/>
        <axis xyz="0 0 1"/>
        
    </joint>


    <!-- joint_1 -->
    <link name="joint_1">
        <inertial>
            <origin xyz="0 0 0" rpy="0 0 0"/>
            <mass value="2"/>
            <inertia ixx="0.01" ixy="0" ixz="0" iyy="0.01" iyz="0" izz="0.01"/>
        </inertial>
        <visual>
            <origin xyz="0 0 0" rpy="0 0 0"/>
            <geometry>
                <box size="0.2 0.2 0.2"/>
            </geometry>
        </visual>
        <collision>
            <origin xyz="0 0 0" rpy="0 0 0"/>
            <geometry>
                <box size="0.2 0.2 0.2"/>
            </geometry>
        </collision>
    </link>
    <!-- Joint: body, joint_1 -->
    <joint name="body_joint_1_joint" type="continuous">
        <parent link="body"/>
        <child link="joint_1"/>
        <origin xyz="0 0 0.6"
                rpy="0 0 0"/>
        <axis xyz="0 0 1"/>
        <limit lower="-0.7853981633974483" upper="0.7853981633974483" effort="999" velocity="999"/>
    </joint>


    <!-- joint_2 -->
    <link name="joint_2">
        <inertial>
            <origin xyz="0 0 0" rpy="0 0 0"/>
            <mass value="2"/>
            <inertia ixx="0.01" ixy="0" ixz="0" iyy="0.01" iyz="0" izz="0.01"/>
        </inertial>
        <visual>
            <origin xyz="0 0 0" rpy="0 0 0"/>
            <geometry>
                <box size="0.2 0.2 0.2"/>
            </geometry>
        </visual>
        <collision>
            <origin xyz="0 0 0" rpy="0 0 0"/>
            <geometry>
                <box size="0.2 0.2 0.2"/>
            </geometry>
        </collision>
    </link>
    <!-- Joint: joint_1, joint_2 -->
    <joint name="joint_1_joint_2_joint" type="continuous">
        <parent link="joint_1"/>
        <child link="joint_2"/>
        <origin xyz="0 0 0.2"
                rpy="0 0 0"/>
        <axis xyz="0 1 0"/>
        <limit lower="-1.5707963267948966" upper="0" effort="999" velocity="999"/>
    </joint>


    <!-- arm -->
    <link name="arm">
        <inertial>
            <origin xyz="0 0 0" rpy="0 0 0"/>
            <mass value="2"/>
            <inertia ixx="0.01" ixy="0" ixz="0" iyy="1.25" iyz="0" izz="1.25"/>
        </inertial>
        <visual>
            <origin xyz="0 0 0" rpy="0 0 0"/>
            <geometry>
                <box size="1.75 0.2 0.2"/>
            </geometry>
        </visual>
        <collision>
            <origin xyz="0 0 0" rpy="0 0 0"/>
            <geometry>
                <box size="1.75 0.2 0.2"/>
            </geometry>
        </collision>
    </link>


    <!-- arm_sensor_0_top -->
    <link name="arm_sensor_0_top">
        <inertial>
            <origin xyz="0 0 0" rpy="0 0 0"/>
            <mass value="0"/>
            <inertia ixx="0" ixy="0" ixz="0" iyy="0" iyz="0" izz="0"/>
        </inertial>
        <visual>
            <origin xyz="0 0 0" rpy="0 0 0"/>
            <geometry>
                <box size="1.75 0.2 0.02"/>
            </geometry>
        </visual>
        <collision>
            <origin xyz="0 0 0" rpy="0 0 0"/>
            <geometry>
                <box size="1.75 0.2 0.02"/>
            </geometry>
        </collision>
    </link>
    <!-- Joint: arm, arm_sensor_0_top -->
    <joint name="arm_arm_sensor_0_top_joint" type="fixed">
        <parent link="arm"/>
        <child link="arm_sensor_0_top"/>
        <origin xyz="0 0 0.1"
                rpy="0 0 0"/>
        <axis xyz="0 1 0"/>
        
    </joint>


    <!-- arm_sensor_0_bottom -->
    <link name="arm_sensor_0_bottom">
        <inertial>
            <origin xyz="0 0 0" rpy="0 0 0"/>
            <mass value="0"/>
            <inertia ixx="0" ixy="0" ixz="0" iyy="0" iyz="0" izz="0"/>
        </inertial>
        <visual>
            <origin xyz="0 0 0" rpy="0 0 0"/>
            <geometry>
                <box size="1.75 0.2 0.02"/>
            </geometry>
        </visual>
        <collision>
            <origin xyz="0 0 0" rpy="0 0 0"/>
            <geometry>
                <box size="1.75 0.2 0.02"/>
            </geometry>
        </collision>
    </link>
    <!-- Joint: arm, arm_sensor_0_bottom -->
    <joint name="arm_arm_sensor_0_bottom_joint" type="fixed">
        <parent link="arm"/>
        <child link="arm_sensor_0_bottom"/>
        <origin xyz="0 0 -0.1"
                rpy="0 0 0"/>
        <axis xyz="0 1 0"/>
        
    </joint>


    <!-- arm_sensor_0_left -->
    <link name="arm_sensor_0_left">
        <inertial>
            <origin xyz="0 0 0" rpy="0 0 0"/>
            <mass value="0"/>
            <inertia ixx="0" ixy="0" ixz="0" iyy="0" iyz="0" izz="0"/>
        </inertial>
        <visual>
            <origin xyz="0 0 0" rpy="0 0 0"/>
            <geometry>
                <box size="1.75 0.02 0.2"/>
            </geometry>
        </visual>
        <collision>
            <origin xyz="0 0 0" rpy="0 0 0"/>
            <geometry>
                <box size="1.75 0.02 0.2"/>
            </geometry>
        </collision>
    </link>
    <!-- Joint: arm, arm_sensor_0_left -->
    <joint name="arm_arm_sensor_0_left_joint" type="fixed">
        <parent link="arm"/>
        <child link="arm_sensor_0_left"/>
        <origin xyz="0 0.1 0"
                rpy="0 0 0"/>
        <axis xyz="0 1 0"/>
        
    </joint>


    <!-- arm_sensor_0_right -->
    <link name="arm_sensor_0_right">
        <inertial>
            <origin xyz="0 0 0" rpy="0 0 0"/>
            <mass value="0"/>
            <inertia ixx="0" ixy="0" ixz="0" iyy="0" iyz="0" izz="0"/>
        </inertial>
        <visual>
            <origin xyz="0 0 0" rpy="0 0 0"/>
            <geometry>
                <box size="1.75 0.02 0.2"/>
            </geometry>
        </visual>
        <collision>
            <origin xyz="0 0 0" rpy="0 0 0"/>
            <geometry>
                <box size="1.75 0.02 0.2"/>
            </geometry>
        </collision>
    </link>
    <!-- Joint: arm, arm_sensor_0_right -->
    <joint name="arm_arm_sensor_0_right_joint" type="fixed">
        <parent link="arm"/>
        <child link="arm_sensor_0_right"/>
        <origin xyz="0 -0.1 0"
                rpy="0 0 0"/>
        <axis xyz="0 1 0"/>
        
    </joint>
    <!-- Joint: joint_2, arm -->
    <joint name="joint_2_arm_joint" type="fixed">
        <parent link="joint_2"/>
        <child link="arm"/>
        <origin xyz="0.975 0 0"
                rpy="0 0 0"/>
        <axis xyz="0 1 0"/>
        
    </joint>


    <!-- hand -->
    <link name="hand">
        <inertial>
            <origin xyz="0 0 0" rpy="0 0 0"/>
            <mass value="2"/>
            <inertia ixx="0.05" ixy="0.05" ixz="0.05" iyy="0.05" iyz="0.05" izz="0.05"/>
        </inertial>
        <visual>
            <origin xyz="0 0 0" rpy="0 0 0"/>
            <geometry>
                <box size="1 0.6000000000000001 1.25"/>
            </geometry>
        </visual>
        <collision>
            <origin xyz="0 0 0" rpy="0 0 0"/>
            <geometry>
                <box size="1 0.6000000000000001 1.25"/>
            </geometry>
        </collision>
    </link>


    <!-- hand_sensor_0_start -->
    <link name="hand_sensor_0_start">
        <inertial>
            <origin xyz="0 0 0" rpy="0 0 0"/>
            <mass value="0"/>
            <inertia ixx="0" ixy="0" ixz="0" iyy="0" iyz="0" izz="0"/>
        </inertial>
        <visual>
            <origin xyz="0 0 0" rpy="0 0 0"/>
            <geometry>
                <box size="0.02 0.6000000000000001 1.25"/>
            </geometry>
        </visual>
        <collision>
            <origin xyz="0 0 0" rpy="0 0 0"/>
            <geometry>
                <box size="0.02 0.6000000000000001 1.25"/>
            </geometry>
        </collision>
    </link>
    <!-- Joint: hand, hand_sensor_0_start -->
    <joint name="hand_hand_sensor_0_start_joint" type="fixed">
        <parent link="hand"/>
        <child link="hand_sensor_0_start"/>
        <origin xyz="0.5 0 0"
                rpy="0 0 0"/>
        <axis xyz="0 1 0"/>
        
    </joint>


    <!-- hand_sensor_0_stop -->
    <link name="hand_sensor_0_stop">
        <inertial>
            <origin xyz="0 0 0" rpy="0 0 0"/>
            <mass value="0"/>
            <inertia ixx="0" ixy="0" ixz="0" iyy="0" iyz="0" izz="0"/>
        </inertial>
        <visual>
            <origin xyz="0 0 0" rpy="0 0 0"/>
            <geometry>
                <box size="0.02 0.6000000000000001 1.25"/>
            </geometry>
        </visual>
        <collision>
            <origin xyz="0 0 0" rpy="0 0 0"/>
            <geometry>
                <box size="0.02 0.6000000000000001 1.25"/>
            </geometry>
        </collision>
    </link>
    <!-- Joint: hand, hand_sensor_0_stop -->
    <joint name="hand_hand_sensor_0_stop_joint" type="fixed">
        <parent link="hand"/>
        <child link="hand_sensor_0_stop"/>
        <origin xyz="-0.5 0 0"
                rpy="0 0 0"/>
        <axis xyz="0 1 0"/>
        
    </joint>


    <!-- hand_sensor_0_top -->
    <link name="hand_sensor_0_top">
        <inertial>
            <origin xyz="0 0 0" rpy="0 0 0"/>
            <mass value="0"/>
            <inertia ixx="0" ixy="0" ixz="0" iyy="0" iyz="0" izz="0"/>
        </inertial>
        <visual>
            <origin xyz="0 0 0" rpy="0 0 0"/>
            <geometry>
                <box size="1.0 0.6000000000000001 0.02"/>
            </geometry>
        </visual>
        <collision>
            <origin xyz="0 0 0" rpy="0 0 0"/>
            <geometry>
                <box size="1.0 0.6000000000000001 0.02"/>
            </geometry>
        </collision>
    </link>
    <!-- Joint: hand, hand_sensor_0_top -->
    <joint name="hand_hand_sensor_0_top_joint" type="fixed">
        <parent link="hand"/>
        <child link="hand_sensor_0_top"/>
        <origin xyz="0 0 0.625"
                rpy="0 0 0"/>
        <axis xyz="0 1 0"/>
        
    </joint>


    <!-- hand_sensor_0_bottom -->
    <link name="hand_sensor_0_bottom">
        <inertial>
            <origin xyz="0 0 0" rpy="0 0 0"/>
            <mass value="0"/>
            <inertia ixx="0" ixy="0" ixz="0" iyy="0" iyz="0" izz="0"/>
        </inertial>
        <visual>
            <origin xyz="0 0 0" rpy="0 0 0"/>
            <geometry>
                <box size="1.0 0.6000000000000001 0.02"/>
            </geometry>
        </visual>
        <collision>
            <origin xyz="0 0 0" rpy="0 0 0"/>
            <geometry>
                <box size="1.0 0.6000000000000001 0.02"/>
            </geometry>
        </collision>
    </link>
    <!-- Joint: hand, hand_sensor_0_bottom -->
    <joint name="hand_hand_sensor_0_bottom_joint" type="fixed">
        <parent link="hand"/>
        <child link="hand_sensor_0_bottom"/>
        <origin xyz="0 0 -0.625"
                rpy="0 0 0"/>
        <axis xyz="0 1 0"/>
        
    </joint>


    <!-- hand_sensor_0_left -->
    <link name="hand_sensor_0_left">
        <inertial>
            <origin xyz="0 0 0" rpy="0 0 0"/>
            <mass value="0"/>
            <inertia ixx="0" ixy="0" ixz="0" iyy="0" iyz="0" izz="0"/>
        </inertial>
        <visual>
            <origin xyz="0 0 0" rpy="0 0 0"/>
            <geometry>
                <box size="1.0 0.02 1.25"/>
            </geometry>
        </visual>
        <collision>
            <origin xyz="0 0 0" rpy="0 0 0"/>
            <geometry>
                <box size="1.0 0.02 1.25"/>
            </geometry>
        </collision>
    </link>
    <!-- Joint: hand, hand_sensor_0_left -->
    <joint name="hand_hand_sensor_0_left_joint" type="fixed">
        <parent link="hand"/>
        <child link="hand_sensor_0_left"/>
        <origin xyz="0 0.30000000000000004 0"
                rpy="0 0 0"/>
        <axis xyz="0 1 0"/>
        
    </joint>


    <!-- hand_sensor_0_right -->
    <link name="hand_sensor_0_right">
        <inertial>
            <origin xyz="0 0 0" rpy="0 0 0"/>
            <mass value="0"/>
            <inertia ixx="0" ixy="0" ixz="0" iyy="0" iyz="0" izz="0"/>
        </inertial>
        <visual>
            <origin xyz="0 0 0" rpy="0 0 0"/>
            <geometry>
                <box size="1.0 0.02 1.25"/>
            </geometry>
        </visual>
        <collision>
            <origin xyz="0 0 0" rpy="0 0 0"/>
            <geometry>
                <box size="1.0 0.02 1.25"/>
            </geometry>
        </collision>
    </link>
    <!-- Joint: hand, hand_sensor_0_right -->
    <joint name="hand_hand_sensor_0_right_joint" type="fixed">
        <parent link="hand"/>
        <child link="hand_sensor_0_right"/>
        <origin xyz="0 -0.30000000000000004 0"
                rpy="0 0 0"/>
        <axis xyz="0 1 0"/>
        
    </joint>
    <!-- Joint: arm, hand -->
    <joint name="arm_hand_joint" type="fixed">
        <parent link="arm"/>
        <child link="hand"/>
        <origin xyz="1.375 0 -0.525"
                rpy="0 0 0"/>
        <axis xyz="0 1 0"/>
        
    </joint>


</robot>